[2023-03-03T15:52:00.923+0000] {taskinstance.py:1083} INFO - Dependencies all met for <TaskInstance: python_operator.hello_with_python scheduled__2022-08-01T00:00:00+00:00 [queued]>
[2023-03-03T15:52:00.933+0000] {taskinstance.py:1083} INFO - Dependencies all met for <TaskInstance: python_operator.hello_with_python scheduled__2022-08-01T00:00:00+00:00 [queued]>
[2023-03-03T15:52:00.933+0000] {taskinstance.py:1279} INFO - 
--------------------------------------------------------------------------------
[2023-03-03T15:52:00.933+0000] {taskinstance.py:1280} INFO - Starting attempt 1 of 1
[2023-03-03T15:52:00.933+0000] {taskinstance.py:1281} INFO - 
--------------------------------------------------------------------------------
[2023-03-03T15:52:00.948+0000] {taskinstance.py:1300} INFO - Executing <Task(PythonOperator): hello_with_python> on 2022-08-01 00:00:00+00:00
[2023-03-03T15:52:00.952+0000] {standard_task_runner.py:55} INFO - Started process 6712 to run task
[2023-03-03T15:52:00.955+0000] {standard_task_runner.py:82} INFO - Running: ['***', 'tasks', 'run', 'python_operator', 'hello_with_python', 'scheduled__2022-08-01T00:00:00+00:00', '--job-id', '40', '--raw', '--subdir', 'DAGS_FOLDER/watch_tfp_services.py', '--cfg-path', '/tmp/tmpkmtnqyzi']
[2023-03-03T15:52:00.956+0000] {standard_task_runner.py:83} INFO - Job 40: Subtask hello_with_python
[2023-03-03T15:52:01.017+0000] {task_command.py:388} INFO - Running <TaskInstance: python_operator.hello_with_python scheduled__2022-08-01T00:00:00+00:00 [running]> on host b5a34fc27f57
[2023-03-03T15:52:01.102+0000] {taskinstance.py:1509} INFO - Exporting the following env vars:
AIRFLOW_CTX_DAG_OWNER=***
AIRFLOW_CTX_DAG_ID=python_operator
AIRFLOW_CTX_TASK_ID=hello_with_python
AIRFLOW_CTX_EXECUTION_DATE=2022-08-01T00:00:00+00:00
AIRFLOW_CTX_TRY_NUMBER=1
AIRFLOW_CTX_DAG_RUN_ID=scheduled__2022-08-01T00:00:00+00:00
[2023-03-03T15:52:01.102+0000] {logging_mixin.py:137} INFO - Hello people from python funtion
[2023-03-03T15:52:01.103+0000] {taskinstance.py:1768} ERROR - Task failed with exception
Traceback (most recent call last):
  File "/home/airflow/.local/lib/python3.7/site-packages/airflow/operators/python.py", line 175, in execute
    return_value = self.execute_callable()
  File "/home/airflow/.local/lib/python3.7/site-packages/airflow/operators/python.py", line 192, in execute_callable
    return self.python_callable(*self.op_args, **self.op_kwargs)
  File "/opt/airflow/dags/watch_tfp_services.py", line 14, in print_hello
    req = requests.get(url, headers=headers, auth=auth)
NameError: name 'headers' is not defined
[2023-03-03T15:52:01.112+0000] {taskinstance.py:1323} INFO - Marking task as FAILED. dag_id=python_operator, task_id=hello_with_python, execution_date=20220801T000000, start_date=20230303T155200, end_date=20230303T155201
[2023-03-03T15:52:01.126+0000] {standard_task_runner.py:105} ERROR - Failed to execute job 40 for task hello_with_python (name 'headers' is not defined; 6712)
[2023-03-03T15:52:01.167+0000] {local_task_job.py:208} INFO - Task exited with return code 1
[2023-03-03T15:52:01.188+0000] {taskinstance.py:2578} INFO - 0 downstream tasks scheduled from follow-on schedule check
